Workbook

Sheet Instrucciones
A1: | | B1: Plantilla de carga inicial · Sistema Sarita
B2: Clientes, Contactos, Direcciones, Prerequisitos de balones y Balones / Cilindros
B4: ORDEN DE LLENADO
B5: 1. Catalogos | C5: Listas fijas (azul) + Gas/TipoBalon/Almacen (amarillo) de referencia.
B6: 2. Empresa | C6: gen_empresa + gen_sucursal (hoja Empresa).
B7: 3. Almacenes | C7: gen_almacen vinculados a sucursal PRINCIPAL.
B8: 4. Gases | C8: pro_producto con es_gas=TRUE.
B9: 5. TiposBalon | C9: bal_tipo_balon vinculados al gas.
B10: 6. Clientes | C10: cli_clientes. El N° documento es llave para el resto.
B11: 7. Plantas | C11: Upgrade/alta de proveedores usados como Propietario=PLANTA.
B12: 8. Contactos | C12: Opcional. Varios por cliente.
B13: 9. Direcciones | C13: Direcciones adicionales (la principal viene de Clientes).
B14: 10. Balones | C14: Cilindros. Requiere prerequisitos + clientes cargados.
B15: Verde | C15: AUTOMÁTICO — no escribir; se calcula solo (verificación de clientes, próxima PH, chequeo de la fila).
B16: Negro | C16: SQL — sentencia generada automáticamente a partir de la fila (solo cuando Chequeo = OK). Para uso del área de sistemas.
B18: REGLAS
B19: Texto azul | C19: Son las celdas donde la empresa escribe. Las celdas con fondo gris son fórmulas: no tocar.
B20: Filas crema | C20: Las primeras filas de cada hoja son EJEMPLOS. Reemplácelas con datos reales.
B21: Columna Chequeo | C21: Debe decir OK en verde. Si sale rojo, indica qué falta o qué está duplicado. Mientras no diga OK, la columna SQL queda vacía.
B22: N° documento | C22: Escribirlo como texto: DNI 8 dígitos, RUC 11 dígitos. No se puede repetir.
B23: Código balón | C23: Es el código pintado/grabado en el cilindro. No se puede repetir.
B24: Propietario del balón | C24: EMPRESA: envase de la empresa que se presta a clientes · CLIENTE: envase que es del cliente · PLANTA: envase del proveedor de recarga (indicar el documento del proveedor) · PROPIA.
B25: Dónde está el balón | C25: Llene Almacén si está en la empresa, o Doc. cliente donde está si lo tiene un cliente. No ambos.
B26: Prueba hidrostática | C26: Si conoce la fecha de la última PH, anótela. Si no, con año y mes de fabricación el sistema calcula la próxima (vigencia 5 años).
B27: Fechas | C27: Formato dd/mm/aaaa.
B28: No borrar | C28: No elimine ni renombre hojas ni columnas: las fórmulas y el SQL dependen de ellas.
B30: PARA SISTEMAS: CARGA A LA BD
B31: Hoja Script SQL | C31: Reúne, en orden, la columna SQL de todas las hojas (Clientes → Contactos → Direcciones → Balones). Seleccione la columna A completa, copie y pegue en psql / DBeaver / pgAdmin sobre la BD destino. Las filas vacías se ignoran.
B32: Requisitos previos | C32: Deben existir en la BD: las listas de gen_lista_opciones (seeds), los productos gas en pro_producto (es_gas = TRUE) con el mismo nombre que Catalogos!Gas, los tipos en bal_tipo_balon con el mismo nombre que Catalogos!TipoBalon, y los almacenes en gen_almacen con el mismo nombre que Catalogos!Almacen. Los nombres se comparan sin distinguir mayúsculas.
B33: Cómo funciona | C33: Clientes y Balones llaman a las funciones cli_crear_clientes / bal_crear_balon (aplican todas las validaciones del sistema y devuelven JSON: si aparece "error" en el resultado, esa fila no se cargó). Contactos y Direcciones son INSERT directos protegidos con NOT EXISTS para no duplicar. Los IDs se resuelven por nombre / N° documento con subconsultas, por eso el orden importa.
B34: Idempotencia | C34: Clientes y Balones rechazan duplicados por documento / código (la función devuelve error y no inserta). Contactos y Direcciones no se insertan si ya existe uno igual para ese cliente. Se puede volver a ejecutar el script sin duplicar datos.
B35: Transacción | C35: Recomendado envolver todo en BEGIN; … COMMIT; y revisar los resultados antes de confirmar.
B37: CORRESPONDENCIA CON LA BD | C37: La fila gris sobre cada encabezado indica el campo de la base de datos al que corresponde la columna.

Sheet Catalogos
A1: Catálogos (listas desplegables)
A2: TipoDocumento | B2: TipoPersona | C2: TipoCliente | D2: PropietarioBalon | E2: EstadoBalon | F2: MarcaCilindro | G2: OrganoInspector | H2: Gas | I2: TipoBalon | J2: Almacen | K2: SiNo
A3: DNI | B3: Persona Natural | C3: Cliente | D3: EMPRESA | E3: DISPONIBLE | F3: JP | G3: NO_APLICA | H3: OXIGENO MEDICINAL | I3: Oxígeno Medicinal 6 m³ | J3: ALMACEN PRINCIPAL | K3: SI
A4: RUC | B4: Persona Jurídica | C4: Paciente | D4: CLIENTE | E4: EN_PODER_CLIENTE | F4: BTIC-JP | G4: OCIA | H4: OXIGENO INDUSTRIAL | I4: Oxígeno Medicinal 10 m³ | J4: ALMACEN LAMBAYEQUE | K4: NO
A5: CARNET EXTRANJERIA | C5: Proveedor | D5: PLANTA | E5: ALQUILADO | F5: JD | G5: DNV | H5: ACETILENO ESTANDAR | I5: Oxígeno Industrial 6 m³
A6: PASAPORTE | C6: Cliente / Proveedor | E6: EN_MANTENIMIENTO | F6: YA | G6: BUREAU_VERITAS | H6: NITROGENO | I6: Oxígeno Industrial 10 m³
A7: SD | C7: Empresa | E7: EN_RECARGA_EXTERNA | F7: LD | G7: LLOYDS | H7: ARGON | I7: Acetileno 5 kg
E8: POR_RECOGER | F8: AMERICANA | G8: OTRO | H8: DIÓXIDO DE CARBONO | I8: Nitrógeno 6 m³
E9: ROBO | F9: BRASILERA | G9: TS | H9: AIRE COMPRIMIDO | I9: Argón Estándar 10 m3
E10: DADO_DE_BAJA | F10: ARGENTINA | G10: NO TIENE | H10: STARGOLD ESTANDAR | I10: Argón Estándar 6 m3
E11: ALMACEN EXTRAVIADO | F11: OTRA | G11: HEXAGONAL (0036) | H11: ETILENO | I11: Argón Estándar 3 m3
E12: CLIENTE EXTRAVIADO | F12: SEFIC | G12: HEXAGONAL (T10) | H12: ACETILENO ESPECIAL | I12: Nitrógeno 10 m³
E13: POR VERIFICAR | F13: ALEMANA | G13: CIRCULO (J) | H13: GAS PROPANO | I13: Nitrógeno 3 m³
F14: YA | G14: ESTRELLA | I14: Dióxido de carbono 25 kg
F15: DOT | G15: TRIANGULO | I15: Dióxido de carbono 30 kg
F16: AGA | I16: Dióxido de carbono 13 kg
F17: SUIZA | I17: Acetileno 1 - 3 kg
F18: OXIGENO CRISTIAN | I18: Acetileno 0 kg
F19: OXYGEN | I19: Acetileno de 3.5 - 5 kg
F20: OXYNET | I20: Acetileno de 8 - 10 kg
F21: WELDWELL | I21: Acetileno de 3.5 - 5.5 kg
I22: Acetileno de 6 - 8 kg
I23: Acetileno de 6 - 7.5 kg
I24: Acetileno de 7 - 9 kg
I25: Acetileno de 4 kg
I26: Acetileno de 1 - 4 kg
I27: Stargold Estandar de 10 m3
I28: Stargold Estandar de 6 m3
I29: Etil 10 m³
I30: Stargold Estandar de 3 m3
I31: Stargold Estandar de 7 m3
I32: ACETILENO ESPECIAL 7 KG
I33: DIOXIDO DE CARBONO 9 KG
... I43: Oxigeno Industrial de 1.5 m3
I44: DIOXIDO DE CARBONO 3 KG | Q44: DIOXIDO DE CARBONO 3 KG
I45: Oxigeno Industrial 2 m³
I46: Oxigeno Industrial 2.5 m³
I47: Dioxido de Carbono de 12 kg
I48: Dióxido de carbono 7 kg
I49: Oxigeno Industrial 1 m³
...

Sheet Empresa
B1: 0a) EMPRESA Y SUCURSAL → gen_empresa + gen_sucursal
B2: Datos mínimos de la empresa Oxígeno Sarita y la sucursal principal. Se cargan ANTES de almacenes, gases, tipos y balones.
A3: (tabla) | B3: ruc | C3: razon_social | D3: nombre_comercial | E3: sucursal_codigo | F3: sucursal_nombre | G3: (sentencia SQL)
A4: Ámbito | B4: RUC | C4: Razón social | D4: Nombre comercial | E4: Código sucursal | F4: Nombre sucursal | G4: SQL
A5: Empresa | B5: 10175332796 | C5: OXIGENO SARITA | D5: OXIGENO SARITA | G5: INSERT INTO gen_empresa (ruc, razon_social, nombre_comercial, estado, id_usuario_creacion, id_usuario_modificacion) SELECT '10175332796', 'OXIGENO SARITA', 'OXIGENO SARITA', 1, 1, 1 WHERE NOT EXISTS (SELECT 1 FROM gen_empresa WHERE ruc = '10175332796');
A6: Sucursal | E6: PRINCIPAL | F6: Sucursal Principal | G6: INSERT INTO gen_sucursal (codigo, nombre, estado, id_usuario_creacion, id_usuario_modificacion) SELECT 'PRINCIPAL', 'Sucursal Principal', 1, 1, 1 WHERE NOT EXISTS (SELECT 1 FROM gen_sucursal WHERE UPPER(codigo) = 'PRINCIPAL');

Sheet Almacenes
B1: 0b) ALMACENES → gen_almacen
B2: Requieren sucursal PRINCIPAL. Los nombres deben coincidir con la columna Almacén de Balones.
A3: (validación) | B3: nombre | C3: sucursal_codigo | D3: (sentencia SQL)
A4: Chequeo | B4: Nombre almacén | C4: Código sucursal | D4: SQL
A5: OK | B5: ALMACEN LAMBAYEQUE | C5: PRINCIPAL | D5: INSERT INTO gen_almacen (id_sucursal, nombre, estado, id_usuario_creacion, id_usuario_modificacion) SELECT s.id, 'ALMACEN LAMBAYEQUE', 1, 1, 1 FROM gen_sucursal s WHERE UPPER(s.codigo) = 'PRINCIPAL' AND NOT EXISTS (SELECT 1 FROM gen_almacen a WHERE UPPER(TRIM(a.nombre)) = UPPER(TRIM('ALMACEN LAMBAYEQUE')));
A6: OK | B6: ALMACEN PRINCIPAL | C6: PRINCIPAL | D6: INSERT INTO gen_almacen (id_sucursal, nombre, estado, id_usuario_creacion, id_usuario_modificacion) SELECT s.id, 'ALMACEN PRINCIPAL', 1, 1, 1 FROM gen_sucursal s WHERE UPPER(s.codigo) = 'PRINCIPAL' AND NOT EXISTS (SELECT 1 FROM gen_almacen a WHERE UPPER(TRIM(a.nombre)) = UPPER(TRIM('ALMACEN PRINCIPAL')));

Sheet Gases
B1: 0c) GASES → pro_producto (es_gas = TRUE)
B2: Productos gas. El nombre debe coincidir con la columna Gas de Balones (sin distinguir mayúsculas).
A3: (validación) | B3: codigo | C3: nombre | D3: (sentencia SQL)
A4: Chequeo | B4: Código | C4: Nombre gas | D4: SQL
A5: OK | B5: GAS-ACE-ESP | C5: ACETILENO ESPECIAL | D5: INSERT INTO pro_producto (codigo, nombre, es_gas, afecta_stock, precio, estado, id_usuario_creacion, id_usuario_modificacion) SELECT 'GAS-ACE-ESP', 'ACETILENO ESPECIAL', TRUE, FALSE, 0, 1, 1, 1 WHERE NOT EXISTS (SELECT 1 FROM pro_producto p WHERE p.es_gas = TRUE AND UPPER(TRIM(p.nombre)) = UPPER(TRIM('ACETILENO ESPECIAL'))) AND NOT EXISTS (SELECT 1 FROM pro_producto p2 WHERE p2.codigo = 'GAS-ACE-ESP');
A6: OK | B6: GAS-ACE-EST | C6: ACETILENO ESTANDAR | D6: INSERT INTO pro_producto (codigo, nombre, es_gas, afecta_stock, precio, estado, id_usuario_creacion, id_usuario_modificacion) SELECT 'GAS-ACE-EST', 'ACETILENO ESTANDAR', TRUE, FALSE, 0, 1, 1, 1 WHERE NOT EXISTS (SELECT 1 FROM pro_producto p WHERE p.es_gas = TRUE AND UPPER(TRIM(p.nombre)) = UPPER(TRIM('ACETILENO ESTANDAR'))) AND NOT EXISTS (SELECT 1 FROM pro_producto p2 WHERE p2.codigo = 'GAS-ACE-EST');
A7: OK | B7: GAS-AIRE-COMPRIMIDO | C7: AIRE COMPRIMIDO | D7: INSERT INTO pro_producto (codigo, nombre, es_gas, afecta_stock, precio, estado, id_usuario_creacion, id_usuario_modificacion) SELECT 'GAS-AIRE-COMPRIMIDO', 'AIRE COMPRIMIDO', TRUE, FALSE, 0, 1, 1, 1 WHERE NOT EXISTS (SELECT 1 FROM pro_producto p WHERE p.es_gas = TRUE AND UPPER(TRIM(p.nombre)) = UPPER(TRIM('AIRE COMPRIMIDO'))) AND NOT EXISTS (SELECT 1 FROM pro_producto p2 WHERE p2.codigo = 'GAS-AIRE-COMPRIMIDO');
A8: OK | B8: GAS-ARGON | C8: ARGON | D8: INSERT INTO pro_producto (codigo, nombre, es_gas, afecta_stock, precio, estado, id_usuario_creacion, id_usuario_modificacion) SELECT 'GAS-ARGON', 'ARGON', TRUE, FALSE, 0, 1, 1, 1 WHERE NOT EXISTS (SELECT 1 FROM pro_producto p WHERE p.es_gas = TRUE AND UPPER(TRIM(p.nombre)) = UPPER(TRIM('ARGON'))) AND NOT EXISTS (SELECT 1 FROM pro_producto p2 WHERE p2.codigo = 'GAS-ARGON');
A9: OK | B9: GAS-CO2 | C9: DIÓXIDO DE CARBONO | D9: INSERT INTO pro_producto (codigo, nombre, es_gas, afecta_stock, precio, estado, id_usuario_creacion, id_usuario_modificacion) SELECT 'GAS-CO2', 'DIÓXIDO DE CARBONO', TRUE, FALSE, 0, 1, 1, 1 WHERE NOT EXISTS (SELECT 1 FROM pro_producto p WHERE p.es_gas = TRUE AND UPPER(TRIM(p.nombre)) = UPPER(TRIM('DIÓXIDO DE CARBONO'))) AND NOT EXISTS (SELECT 1 FROM pro_producto p2 WHERE p2.codigo = 'GAS-CO2');
A10: OK | B10: GAS-ETILENO | C10: ETILENO | D10: INSERT INTO pro_producto (codigo, nombre, es_gas, afecta_stock, precio, estado, id_usuario_creacion, id_usuario_modificacion) SELECT 'GAS-ETILENO', 'ETILENO', TRUE, FALSE, 0, 1, 1, 1 WHERE NOT EXISTS (SELECT 1 FROM pro_producto p WHERE p.es_gas = TRUE AND UPPER(TRIM(p.nombre)) = UPPER(TRIM('ETILENO'))) AND NOT EXISTS (SELECT 1 FROM pro_producto p2 WHERE p2.codigo = 'GAS-ETILENO');
A11: OK | B11: GAS-PROPANO | C11: GAS PROPANO | D11: INSERT INTO pro_producto (codigo, nombre, es_gas, afecta_stock, precio, estado, id_usuario_creacion, id_usuario_modificacion) SELECT 'GAS-PROPANO', 'GAS PROPANO', TRUE, FALSE, 0, 1, 1, 1 WHERE NOT EXISTS (SELECT 1 FROM pro_producto p WHERE p.es_gas = TRUE AND UPPER(TRIM(p.nombre)) = UPPER(TRIM('GAS PROPANO'))) AND NOT EXISTS (SELECT 1 FROM pro_producto p2 WHERE p2.codigo = 'GAS-PROPANO');
A12: OK | B12: GAS-NITROGENO | C12: NITROGENO | D12: INSERT INTO pro_producto (codigo, nombre, es_gas, afecta_stock, precio, estado, id_usuario_creacion, id_usuario_modificacion) SELECT 'GAS-NITROGENO', 'NITROGENO', TRUE, FALSE, 0, 1, 1, 1 WHERE NOT EXISTS (SELECT 1 FROM pro_producto p WHERE p.es_gas = TRUE AND UPPER(TRIM(p.nombre)) = UPPER(TRIM('NITROGENO'))) AND NOT EXISTS (SELECT 1 FROM pro_producto p2 WHERE p2.codigo = 'GAS-NITROGENO');
A13: OK | B13: GAS-OXI-IND | C13: OXIGENO INDUSTRIAL | D13: INSERT INTO pro_producto (codigo, nombre, es_gas, afecta_stock, precio, estado, id_usuario_creacion, id_usuario_modificacion) SELECT 'GAS-OXI-IND', 'OXIGENO INDUSTRIAL', TRUE, FALSE, 0, 1, 1, 1 WHERE NOT EXISTS (SELECT 1 FROM pro_producto p WHERE p.es_gas = TRUE AND UPPER(TRIM(p.nombre)) = UPPER(TRIM('OXIGENO INDUSTRIAL'))) AND NOT EXISTS (SELECT 1 FROM pro_producto p2 WHERE p2.codigo = 'GAS-OXI-IND');
A14: OK | B14: GAS-OXI-MED | C14: OXIGENO MEDICINAL | D14: INSERT INTO pro_producto (codigo, nombre, es_gas, afecta_stock, precio, estado, id_usuario_creacion, id_usuario_modificacion) SELECT 'GAS-OXI-MED', 'OXIGENO MEDICINAL', TRUE, FALSE, 0, 1, 1, 1 WHERE NOT EXISTS (SELECT 1 FROM pro_producto p WHERE p.es_gas = TRUE AND UPPER(TRIM(p.nombre)) = UPPER(TRIM('OXIGENO MEDICINAL'))) AND NOT EXISTS (SELECT 1 FROM pro_producto p2 WHERE p2.codigo = 'GAS-OXI-MED');
A15: OK | B15: GAS-STARGOLD | C15: STARGOLD ESTANDAR | D15: INSERT INTO pro_producto (codigo, nombre, es_gas, afecta_stock, precio, estado, id_usuario_creacion, id_usuario_modificacion) SELECT 'GAS-STARGOLD', 'STARGOLD ESTANDAR', TRUE, FALSE, 0, 1, 1, 1 WHERE NOT EXISTS (SELECT 1 FROM pro_producto p WHERE p.es_gas = TRUE AND UPPER(TRIM(p.nombre)) = UPPER(TRIM('STARGOLD ESTANDAR'))) AND NOT EXISTS (SELECT 1 FROM pro_producto p2 WHERE p2.codigo = 'GAS-STARGOLD');

Sheet TiposBalon
B1: 0d) TIPOS DE BALÓN → bal_tipo_balon
B2: Cada tipo se vincula a un gas (pro_producto). Capacidad/unidad se inferen del nombre cuando es posible. El nombre debe coincidir con Tipo balón de la hoja Balones.
A3: (validación) | B3: nombre | C3: gas | D3: capacidad | E3: unidad | F3: (sentencia SQL)
A4: Chequeo | B4: Nombre tipo balón | C4: Gas | D4: Capacidad | E4: Unidad (MT3/KG) | F4: SQL
A5: OK | B5: Acetileno 0 kg | C5: ACETILENO ESTANDAR | D5: 0 | E5: KG | F5: INSERT INTO bal_tipo_balon (nombre, id_gas, capacidad, id_unidad_medida, estado, vigencia_ph_anios, id_usuario_creacion, id_usuario_modificacion) SELECT 'Acetileno 0 kg', p.id, 0.0, (SELECT id FROM gen_lista_opciones lo JOIN gen_lista l ON l.id = lo.id_lista WHERE l.nombre = 'UnidadMedida' AND UPPER(lo.nombre) = UPPER('KG') AND lo.estado = 1 LIMIT 1), 1, 5, 1, 1 FROM pro_producto p WHERE p.es_gas = TRUE AND UPPER(TRIM(p.nombre)) = UPPER(TRIM('ACETILENO ESTANDAR')) AND NOT EXISTS (SELECT 1 FROM bal_tipo_balon t WHERE UPPER(TRIM(t.nombre)) = UPPER(TRIM('Acetileno 0 kg'))) LIMIT 1;
A6: OK | B6: Acetileno 1 - 3 kg | C6: ACETILENO ESTANDAR | D6: 3 | E6: KG | F6: INSERT INTO bal_tipo_balon (nombre, id_gas, capacidad, id_unidad_medida, estado, vigencia_ph_anios, id_usuario_creacion, id_usuario_modificacion) SELECT 'Acetileno 1 - 3 kg', p.id, 3.0, (SELECT id FROM gen_lista_opciones lo JOIN gen_lista l ON l.id = lo.id_lista WHERE l.nombre = 'UnidadMedida' AND UPPER(lo.nombre) = UPPER('KG') AND lo.estado = 1 LIMIT 1), 1, 5, 1, 1 FROM pro_producto p WHERE p.es_gas = TRUE AND UPPER(TRIM(p.nombre)) = UPPER(TRIM('ACETILENO ESTANDAR')) AND NOT EXISTS (SELECT 1 FROM bal_tipo_balon t WHERE UPPER(TRIM(t.nombre)) = UPPER(TRIM('Acetileno 1 - 3 kg'))) LIMIT 1;
A7: OK | B7: Acetileno 5 kg | C7: ACETILENO ESTANDAR | D7: 5 | E7: KG | F7: INSERT INTO bal_tipo_balon (nombre, id_gas, capacidad, id_unidad_medida, estado, vigencia_ph_anios, id_usuario_creacion, id_usuario_modificacion) SELECT 'Acetileno 5 kg', p.id, 5.0, (SELECT id FROM gen_lista_opciones lo JOIN gen_lista l ON l.id = lo.id_lista WHERE l.nombre = 'UnidadMedida' AND UPPER(lo.nombre) = UPPER('KG') AND lo.estado = 1 LIMIT 1), 1, 5, 1, 1 FROM pro_producto p WHERE p.es_gas = TRUE AND UPPER(TRIM(p.nombre)) = UPPER(TRIM('ACETILENO ESTANDAR')) AND NOT EXISTS (SELECT 1 FROM bal_tipo_balon t WHERE UPPER(TRIM(t.nombre)) = UPPER(TRIM('Acetileno 5 kg'))) LIMIT 1;
A8: OK | B8: Acetileno de 1 - 4 kg | C8: ACETILENO ESTANDAR | D8: 4 | E8: KG | F8: INSERT INTO bal_tipo_balon (nombre, id_gas, capacidad, id_unidad_medida, estado, vigencia_ph_anios, id_usuario_creacion, id_usuario_modificacion) SELECT 'Acetileno de 1 - 4 kg', p.id, 4.0, (SELECT id FROM gen_lista_opciones lo JOIN gen_lista l ON l.id = lo.id_lista WHERE l.nombre = 'UnidadMedida' AND UPPER(lo.nombre) = UPPER('KG') AND lo.estado = 1 LIMIT 1), 1, 5, 1, 1 FROM pro_producto p WHERE p.es_gas = TRUE AND UPPER(TRIM(p.nombre)) = UPPER(TRIM('ACETILENO ESTANDAR')) AND NOT EXISTS (SELECT 1 FROM bal_tipo_balon t WHERE UPPER(TRIM(t.nombre)) = UPPER(TRIM('Acetileno de 1 - 4 kg'))) LIMIT 1;
A9: FALTA gas | B9: Acetileno de 10 kg | D9: 10 | E9: KG
A10: FALTA gas | B10: Acetileno de 2.5 kg | D10: 2.5 | E10: KG
A11: OK | B11: Acetileno de 3.5 - 5 kg | C11: ACETILENO ESTANDAR | D11: 5 | E11: KG | F11: INSERT INTO bal_tipo_balon (nombre, id_gas, capacidad, id_unidad_medida, estado, vigencia_ph_anios, id_usuario_creacion, id_usuario_modificacion) SELECT 'Acetileno de 3.5 - 5 kg', p.id, 5.0, (SELECT id FROM gen_lista_opciones lo JOIN gen_lista l ON l.id = lo.id_lista WHERE l.nombre = 'UnidadMedida' AND UPPER(lo.nombre) = UPPER('KG') AND lo.estado = 1 LIMIT 1), 1, 5, 1, 1 FROM pro_producto p WHERE p.es_gas = TRUE AND UPPER(TRIM(p.nombre)) = UPPER(TRIM('ACETILENO ESTANDAR')) AND NOT EXISTS (SELECT 1 FROM bal_tipo_balon t WHERE UPPER(TRIM(t.nombre)) = UPPER(TRIM('Acetileno de 3.5 - 5 kg'))) LIMIT 1;
A12: OK | B12: Acetileno de 3.5 - 5.5 kg | C12: ACETILENO ESTANDAR | D12: 5.5 | E12: KG | F12: INSERT INTO bal_tipo_balon (nombre, id_gas, capacidad, id_unidad_medida, estado, vigencia_ph_anios, id_usuario_creacion, id_usuario_modificacion) SELECT 'Acetileno de 3.5 - 5.5 kg', p.id, 5.5, (SELECT id FROM gen_lista_opciones lo JOIN gen_lista l ON l.id = lo.id_lista WHERE l.nombre = 'UnidadMedida' AND UPPER(lo.nombre) = UPPER('KG') AND lo.estado = 1 LIMIT 1), 1, 5, 1, 1 FROM pro_producto p WHERE p.es_gas = TRUE AND UPPER(TRIM(p.nombre)) = UPPER(TRIM('ACETILENO ESTANDAR')) AND NOT EXISTS (SELECT 1 FROM bal_tipo_balon t WHERE UPPER(TRIM(t.nombre)) = UPPER(TRIM('Acetileno de 3.5 - 5.5 kg'))) LIMIT 1;
A13: OK | B13: Acetileno de 4 kg | C13: ACETILENO ESTANDAR | D13: 4 | E13: KG | F13: INSERT INTO bal_tipo_balon (nombre, id_gas, capacidad, id_unidad_medida, estado, vigencia_ph_anios, id_usuario_creacion, id_usuario_modificacion) SELECT 'Acetileno de 4 kg', p.id, 4.0, (SELECT id FROM gen_lista_opciones lo JOIN gen_lista l ON l.id = lo.id_lista WHERE l.nombre = 'UnidadMedida' AND UPPER(lo.nombre) = UPPER('KG') AND lo.estado = 1 LIMIT 1), 1, 5, 1, 1 FROM pro_producto p WHERE p.es_gas = TRUE AND UPPER(TRIM(p.nombre)) = UPPER(TRIM('ACETILENO ESTANDAR')) AND NOT EXISTS (SELECT 1 FROM bal_tipo_balon t WHERE UPPER(TRIM(t.nombre)) = UPPER(TRIM('Acetileno de 4 kg'))) LIMIT 1;
A14: OK | B14: Acetileno de 6 - 7.5 kg | C14: ACETILENO ESTANDAR | D14: 7.5 | E14: KG | F14: INSERT INTO bal_tipo_balon (nombre, id_gas, capacidad, id_unidad_medida, estado, vigencia_ph_anios, id_usuario_creacion, id_usuario_modificacion) SELECT 'Acetileno de 6 - 7.5 kg', p.id, 7.5, (SELECT id FROM gen_lista_opciones lo JOIN gen_lista l ON l.id = lo.id_lista WHERE l.nombre = 'UnidadMedida' AND UPPER(lo.nombre) = UPPER('KG') AND lo.estado = 1 LIMIT 1), 1, 5, 1, 1 FROM pro_producto p WHERE p.es_gas = TRUE AND UPPER(TRIM(p.nombre)) = UPPER(TRIM('ACETILENO ESTANDAR')) AND NOT EXISTS (SELECT 1 FROM bal_tipo_balon t WHERE UPPER(TRIM(t.nombre)) = UPPER(TRIM('Acetileno de 6 - 7.5 kg'))) LIMIT 1;
A15: OK | B15: Acetileno de 6 - 8 kg | C15: ACETILENO ESTANDAR | D15: 8 | E15: KG | F15: INSERT INTO bal_tipo_balon (nombre, id_gas, capacidad, id_unidad_medida, estado, vigencia_ph_anios, id_usuario_creacion, id_usuario_modificacion) SELECT 'Acetileno de 6 - 8 kg', p.id, 8.0, (SELECT id FROM gen_lista_opciones lo JOIN gen_lista l ON l.id = lo.id_lista WHERE l.nombre = 'UnidadMedida' AND UPPER(lo.nombre) = UPPER('KG') AND lo.estado = 1 LIMIT 1), 1, 5, 1, 1 FROM pro_producto p WHERE p.es_gas = TRUE AND UPPER(TRIM(p.nombre)) = UPPER(TRIM('ACETILENO ESTANDAR')) AND NOT EXISTS (SELECT 1 FROM bal_tipo_balon t WHERE UPPER(TRIM(t.nombre)) = UPPER(TRIM('Acetileno de 6 - 8 kg'))) LIMIT 1;
A16: OK | B16: Acetileno de 7 - 9 kg | C16: ACETILENO ESTANDAR | D16: 9 | E16: KG | F16: INSERT INTO bal_tipo_balon (nombre, id_gas, capacidad, id_unidad_medida, estado, vigencia_ph_anios, id_usuario_creacion, id_usuario_modificacion) SELECT 'Acetileno de 7 - 9 kg', p.id, 9.0, (SELECT id FROM gen_lista_opciones lo JOIN gen_lista l ON l.id = lo.id_lista WHERE l.nombre = 'UnidadMedida' AND UPPER(lo.nombre) = UPPER('KG') AND lo.estado = 1 LIMIT 1), 1, 5, 1, 1 FROM pro_producto p WHERE p.es_gas = TRUE AND UPPER(TRIM(p.nombre)) = UPPER(TRIM('ACETILENO ESTANDAR')) AND NOT EXISTS (SELECT 1 FROM bal_tipo_balon t WHERE UPPER(TRIM(t.nombre)) = UPPER(TRIM('Acetileno de 7 - 9 kg'))) LIMIT 1;
A17: FALTA gas | B17: Acetileno de 7 kg | D17: 7 | E17: KG
A18: OK | B18: Acetileno de 8 - 10 kg | C18: ACETILENO ESTANDAR | D18: 10 | E18: KG | F18: INSERT INTO bal_tipo_balon (nombre, id_gas, capacidad, id_unidad_medida, estado, vigencia_ph_anios, id_usuario_creacion, id_usuario_modificacion) SELECT 'Acetileno de 8 - 10 kg', p.id, 10.0, (SELECT id FROM gen_lista_opciones lo JOIN gen_lista l ON l.id = lo.id_lista WHERE l.nombre = 'UnidadMedida' AND UPPER(lo.nombre) = UPPER('KG') AND lo.estado = 1 LIMIT 1), 1, 5, 1, 1 FROM pro_producto p WHERE p.es_gas = TRUE AND UPPER(TRIM(p.nombre)) = UPPER(TRIM('ACETILENO ESTANDAR')) AND NOT EXISTS (SELECT 1 FROM bal_tipo_balon t WHERE UPPER(TRIM(t.nombre)) = UPPER(TRIM('Acetileno de 8 - 10 kg'))) LIMIT 1;
A19: OK | B19: Acetileno de 8kg | C19: ACETILENO ESPECIAL | D19: 8 | E19: KG | F19: INSERT INTO bal_tipo_balon (nombre, id_gas, capacidad, id_unidad_medida, estado, vigencia_ph_anios, id_usuario_creacion, id_usuario_modificacion) SELECT 'Acetileno de 8kg', p.id, 8.0, (SELECT id FROM gen_lista_opciones lo JOIN gen_lista l ON l.id = lo.id_lista WHERE l.nombre = 'UnidadMedida' AND UPPER(lo.nombre) = UPPER('KG') AND lo.estado = 1 LIMIT 1), 1, 5, 1, 1 FROM pro_producto p WHERE p.es_gas = TRUE AND UPPER(TRIM(p.nombre)) = UPPER(TRIM('ACETILENO ESPECIAL')) AND NOT EXISTS (SELECT 1 FROM bal_tipo_balon t WHERE UPPER(TRIM(t.nombre)) = UPPER(TRIM('Acetileno de 8kg'))) LIMIT 1;
A20: FALTA gas | B20: ACETILENO ESPECIAL 7 KG | D20: 7 | E20: KG
A21: OK | B21: Argón Estándar 10 m3 | C21: ARGON | D21: 10 | E21: MT3 | F21: INSERT INTO bal_tipo_balon (nombre, id_gas, capacidad, id_unidad_medida, estado, vigencia_ph_anios, id_usuario_creacion, id_usuario_modificacion) SELECT 'Argón Estándar 10 m3', p.id, 10.0, (SELECT id FROM gen_lista_opciones lo JOIN gen_lista l ON l.id = lo.id_lista WHERE l.nombre = 'UnidadMedida' AND UPPER(lo.nombre) = UPPER('MT3') AND lo.estado = 1 LIMIT 1), 1, 5, 1, 1 FROM pro_producto p WHERE p.es_gas = TRUE AND UPPER(TRIM(p.nombre)) = UPPER(TRIM('ARGON')) AND NOT EXISTS (SELECT 1 FROM bal_tipo_balon t WHERE UPPER(TRIM(t.nombre)) = UPPER(TRIM('Argón Estándar 10 m3'))) LIMIT 1;
A22: OK | B22: Argón Estándar 3 m3 | C22: ARGON | D22: 3 | E22: MT3 | F22: INSERT INTO bal_tipo_balon (nombre, id_gas, capacidad, id_unidad_medida, estado, vigencia_ph_anios, id_usuario_creacion, id_usuario_modificacion) SELECT 'Argón Estándar 3 m3', p.id, 3.0, (SELECT id FROM gen_lista_opciones lo JOIN gen_lista l ON l.id = lo.id_lista WHERE l.nombre = 'UnidadMedida' AND UPPER(lo.nombre) = UPPER('MT3') AND lo.estado = 1 LIMIT 1), 1, 5, 1, 1 FROM pro_producto p WHERE p.es_gas = TRUE AND UPPER(TRIM(p.nombre)) = UPPER(TRIM('ARGON')) AND NOT EXISTS (SELECT 1 FROM bal_tipo_balon t WHERE UPPER(TRIM(t.nombre)) = UPPER(TRIM('Argón Estándar 3 m3'))) LIMIT 1;
A23: OK | B23: Argón Estándar 6 m3 | C23: ARGON | D23: 6 | E23: MT3 | F23: INSERT INTO bal_tipo_balon (nombre, id_gas, capacidad, id_unidad_medida, estado, vigencia_ph_anios, id_usuario_creacion, id_usuario_modificacion) SELECT 'Argón Estándar 6 m3', p.id, 6.0, (SELECT id FROM gen_lista_opciones lo JOIN gen_lista l ON l.id = lo.id_lista WHERE l.nombre = 'UnidadMedida' AND UPPER(lo.nombre) = UPPER('MT3') AND lo.estado = 1 LIMIT 1), 1, 5, 1, 1 FROM pro_producto p WHERE p.es_gas = TRUE AND UPPER(TRIM(p.nombre)) = UPPER(TRIM('ARGON')) AND NOT EXISTS (SELECT 1 FROM bal_tipo_balon t WHERE UPPER(TRIM(t.nombre)) = UPPER(TRIM('Argón Estándar 6 m3'))) LIMIT 1;
A24: OK | B24: Dióxido de carbono 13 kg | C24: DIÓXIDO DE CARBONO | D24: 13 | E24: KG | F24: INSERT INTO bal_tipo_balon (nombre, id_gas, capacidad, id_unidad_medida, estado, vigencia_ph_anios, id_usuario_creacion, id_usuario_modificacion) SELECT 'Dióxido de carbono 13 kg', p.id, 13.0, (SELECT id FROM gen_lista_opciones lo JOIN gen_lista l ON l.id = lo.id_lista WHERE l.nombre = 'UnidadMedida' AND UPPER(lo.nombre) = UPPER('KG') AND lo.estado = 1 LIMIT 1), 1, 5, 1, 1 FROM pro_producto p WHERE p.es_gas = TRUE AND UPPER(TRIM(p.nombre)) = UPPER(TRIM('DIÓXIDO DE CARBONO')) AND NOT EXISTS (SELECT 1 FROM bal_tipo_balon t WHERE UPPER(TRIM(t.nombre)) = UPPER(TRIM('Dióxido de carbono 13 kg'))) LIMIT 1;
A25: OK | B25: Dióxido de carbono 25 kg | C25: DIÓXIDO DE CARBONO | D25: 25 | E25: KG | F25: INSERT INTO bal_tipo_balon (nombre, id_gas, capacidad, id_unidad_medida, estado, vigencia_ph_anios, id_usuario_creacion, id_usuario_modificacion) SELECT 'Dióxido de carbono 25 kg', p.id, 25.0, (SELECT id FROM gen_lista_opciones lo JOIN gen_lista l ON l.id = lo.id_lista WHERE l.nombre = 'UnidadMedida' AND UPPER(lo.nombre) = UPPER('KG') AND lo.estado = 1 LIMIT 1), 1, 5, 1, 1 FROM pro_producto p WHERE p.es_gas = TRUE AND UPPER(TRIM(p.nombre)) = UPPER(TRIM('DIÓXIDO DE CARBONO')) AND NOT EXISTS (SELECT 1 FROM bal_tipo_balon t WHERE UPPER(TRIM(t.nombre)) = UPPER(TRIM('Dióxido de carbono 25 kg'))) LIMIT 1;
A26: OK | B26: DIOXIDO DE CARBONO 3 KG | C26: DIÓXIDO DE CARBONO | D26: 3 | E26: KG | F26: INSERT INTO bal_tipo_balon (nombre, id_gas, capacidad, id_unidad_medida, estado, vigencia_ph_anios, id_usuario_creacion, id_usuario_modificacion) SELECT 'DIOXIDO DE CARBONO 3 KG', p.id, 3.0, (SELECT id FROM gen_lista_opciones lo JOIN gen_lista l ON l.id = lo.id_lista WHERE l.nombre = 'UnidadMedida' AND UPPER(lo.nombre) = UPPER('KG') AND lo.estado = 1 LIMIT 1), 1, 5, 1, 1 FROM pro_producto p WHERE p.es_gas = TRUE AND UPPER(TRIM(p.nombre)) = UPPER(TRIM('DIÓXIDO DE CARBONO')) AND NOT EXISTS (SELECT 1 FROM bal_tipo_balon t WHERE UPPER(TRIM(t.nombre)) = UPPER(TRIM('DIOXIDO DE CARBONO 3 KG'))) LIMIT 1;
A27: OK | B27: Dióxido de carbono 30 kg | C27: DIÓXIDO DE CARBONO | D27: 30 | E27: KG | F27: INSERT INTO bal_tipo_balon (nombre, id_gas, capacidad, id_unidad_medida, estado, vigencia_ph_anios, id_usuario_creacion, id_usuario_modificacion) SELECT 'Dióxido de carbono 30 kg', p.id, 30.0, (SELECT id FROM gen_lista_opciones lo JOIN gen_lista l ON l.id = lo.id_lista WHERE l.nombre = 'UnidadMedida' AND UPPER(lo.nombre) = UPPER('KG') AND lo.estado = 1 LIMIT 1), 1, 5, 1, 1 FROM pro_producto p WHERE p.es_gas = TRUE AND UPPER(TRIM(p.nombre)) = UPPER(TRIM('DIÓXIDO DE CARBONO')) AND NOT EXISTS (SELECT 1 FROM bal_tipo_balon t WHERE UPPER(TRIM(t.nombre)) = UPPER(TRIM('Dióxido de carbono 30 kg'))) LIMIT 1;
A28: OK | B28: Dióxido de carbono 7 kg | C28: DIÓXIDO DE CARBONO | D28: 7 | E28: KG | F28: INSERT INTO bal_tipo_balon (nombre, id_gas, capacidad, id_unidad_medida, estado, vigencia_ph_anios, id_usuario_creacion, id_usuario_modificacion) SELECT 'Dióxido de carbono 7 kg', p.id, 7.0, (SELECT id FROM gen_lista_opciones lo JOIN gen_lista l ON l.id = lo.id_lista WHERE l.nombre = 'UnidadMedida' AND UPPER(lo.nombre) = UPPER('KG') AND lo.estado = 1 LIMIT 1), 1, 5, 1, 1 FROM pro_producto p WHERE p.es_gas = TRUE AND UPPER(TRIM(p.nombre)) = UPPER(TRIM('DIÓXIDO DE CARBONO')) AND NOT EXISTS (SELECT 1 FROM bal_tipo_balon t WHERE UPPER(TRIM(t.nombre)) = UPPER(TRIM('Dióxido de carbono 7 kg'))) LIMIT 1;
A29: OK | B29: DIOXIDO DE CARBONO 9 KG | C29: DIÓXIDO DE CARBONO | D29: 9 | E29: KG | F29: INSERT INTO bal_tipo_balon (nombre, id_gas, capacidad, id_unidad_medida, estado, vigencia_ph_anios, id_usuario_creacion, id_usuario_modificacion) SELECT 'DIOXIDO DE CARBONO 9 KG', p.id, 9.0, (SELECT id FROM gen_lista_opciones lo JOIN gen_lista l ON l.id = lo.id_lista WHERE l.nombre = 'UnidadMedida' AND UPPER(lo.nombre) = UPPER('KG') AND lo.estado = 1 LIMIT 1), 1, 5, 1, 1 FROM pro_producto p WHERE p.es_gas = TRUE AND UPPER(TRIM(p.nombre)) = UPPER(TRIM('DIÓXIDO DE CARBONO')) AND NOT EXISTS (SELECT 1 FROM bal_tipo_balon t WHERE UPPER(TRIM(t.nombre)) = UPPER(TRIM('DIOXIDO DE CARBONO 9 KG'))) LIMIT 1;
A30: OK | B30: Dioxido de Carbono de 12 kg | C30: DIÓXIDO DE CARBONO | D30: 12 | E30: KG | F30: INSERT INTO bal_tipo_balon (nombre, id_gas, capacidad, id_unidad_medida, estado, vigencia_ph_anios, id_usuario_creacion, id_usuario_modificacion) SELECT 'Dioxido de Carbono de 12 kg', p.id, 12.0, (SELECT id FROM gen_lista_opciones lo JOIN gen_lista l ON l.id = lo.id_lista WHERE l.nombre = 'UnidadMedida' AND UPPER(lo.nombre) = UPPER('KG') AND lo.estado = 1 LIMIT 1), 1, 5, 1, 1 FROM pro_producto p WHERE p.es_gas = TRUE AND UPPER(TRIM(p.nombre)) = UPPER(TRIM('DIÓXIDO DE CARBONO')) AND NOT EXISTS (SELECT 1 FROM bal_tipo_balon t WHERE UPPER(TRIM(t.nombre)) = UPPER(TRIM('Dioxido de Carbono de 12 kg'))) LIMIT 1;
A31: OK | B31: Etil 10 m³ | C31: ETILENO | D31: 10 | E31: MT3 | F31: INSERT INTO bal_tipo_balon (nombre, id_gas, capacidad, id_unidad_medida, estado, vigencia_ph_anios, id_usuario_creacion, id_usuario_modificacion) SELECT 'Etil 10 m³', p.id, 10.0, (SELECT id FROM gen_lista_opciones lo JOIN gen_lista l ON l.id = lo.id_lista WHERE l.nombre = 'UnidadMedida' AND UPPER(lo.nombre) = UPPER('MT3') AND lo.estado = 1 LIMIT 1), 1, 5, 1, 1 FROM pro_producto p WHERE p.es_gas = TRUE AND UPPER(TRIM(p.nombre)) = UPPER(TRIM('ETILENO')) AND NOT EXISTS (SELECT 1 FROM bal_tipo_balon t WHERE UPPER(TRIM(t.nombre)) = UPPER(TRIM('Etil 10 m³'))) LIMIT 1;
A32: OK | B32: Gas Propano 10 kg | C32: OXIGENO INDUSTRIAL | D32: 10 | E32: KG | F32: INSERT INTO bal_tipo_balon (nombre, id_gas, capacidad, id_unidad_medida, estado, vigencia_ph_anios, id_usuario_creacion, id_usuario_modificacion) SELECT 'Gas Propano 10 kg', p.id, 10.0, (SELECT id FROM gen_lista_opciones lo JOIN gen_lista l ON l.id = lo.id_lista WHERE l.nombre = 'UnidadMedida' AND UPPER(lo.nombre) = UPPER('KG') AND lo.estado = 1 LIMIT 1), 1, 5, 1, 1 FROM pro_producto p WHERE p.es_gas = TRUE AND UPPER(TRIM(p.nombre)) = UPPER(TRIM('OXIGENO INDUSTRIAL')) AND NOT EXISTS (SELECT 1 FROM bal_tipo_balon t WHERE UPPER(TRIM(t.nombre)) = UPPER(TRIM('Gas Propano 10 kg'))) LIMIT 1;
... A55: OK | B55: Stargold Estandar de 7 m3 | C55: STARGOLD ESTANDAR | D55: 7 | E55: MT3 | F55: INSERT INTO bal_tipo_balon (nombre, id_gas, capacidad, id_unidad_medida, estado, vigencia_ph_anios, id_usuario_creacion, id_usuario_modificacion) SELECT 'Stargold Estandar de 7 m3', p.id, 7.0, (SELECT id FROM gen_lista_opciones lo JOIN gen_lista l ON l.id = lo.id_lista WHERE l.nombre = 'UnidadMedida' AND UPPER(lo.nombre) = UPPER('MT3') AND lo.estado = 1 LIMIT 1), 1, 5, 1, 1 FROM pro_producto p WHERE p.es_gas = TRUE AND UPPER(TRIM(p.nombre)) = UPPER(TRIM('STARGOLD ESTANDAR')) AND NOT EXISTS (SELECT 1 FROM bal_tipo_balon t WHERE UPPER(TRIM(t.nombre)) = UPPER(TRIM('Stargold Estandar de 7 m3'))) LIMIT 1;

Sheet Clientes
B1: 1) CLIENTES → tabla cli_clientes (función cli_crear_clientes)
B2: Llenar PRIMERO esta hoja. Debe indicar Razón social (empresa) O Nombres (persona). El N° de documento no puede repetirse y se usa como llave en las demás hojas. La dirección de esta hoja queda como dirección principal.
A3: (validación) | B3: id_tipo_documento | C3: numero_documento | D3: razon_social | E3: nombres | F3: apellido_paterno | G3: apellido_materno | H3: id_tipo_persona | I3: id_tipo_cliente | J3: cli_direcciones.direccion (principal) | K3: cli_direcciones.referencia | L3: telefono | M3: email | N3: codigo_interno | O3: observacion | P3: (sentencia SQL)
A4: Chequeo | B4: Tipo documento | C4: N° documento | D4: Razón social | E4: Nombres | F4: Apellido paterno | G4: Apellido materno | H4: Tipo persona | I4: Tipo cliente | J4: Dirección principal | K4: Referencia | L4: Teléfono | M4: Email | N4: Código interno | O4: Observación | P4: SQL
A5: =IF(AND(D5="",E5="",C5=""),"",IF(AND(D5="",E5=""),"FALTA razón social o nombres",IF(AND(C5<>"",SUMPRODUCT(--($C$5:$C$549=C5))>1),"DOCUMENTO DUPLICADO",IF(AND(B5="DNI",C5<>"",LEN(C5&"")<>8),"DNI debe tener 8 dígitos",IF(AND(B5="RUC",C5<>"",LEN(C5&"")<>11),"RUC debe tener 11 dígitos",IF(AND(N5<>"",SUMPRODUCT(--($N$5:$N$549=N5))>1),"CÓDIGO INTERNO DUPLICADO","OK")))))) | B5: RUC | C5: 20608006738 | D5: ACEROX GUZMAN S.A.C. | H5: Persona Jurídica | I5: Cliente | P5: =IF(A5<>"OK","","SELECT cli_crear_clientes(p_codigo_interno => "&IF(TRIM(N5&"")="","NULL","'"&SUBSTITUTE(TRIM(N5),"'","''")&"'")&", p_razon_social => "&IF(TRIM(D5&"")="","NULL","'"&SUBSTITUTE(TRIM(D5),"'","''")&"'")&", p_id_tipo_cliente => "&IF(TRIM(I5&"")="","NULL","(SELECT lo.id FROM gen_lista_opciones lo JOIN gen_lista l ON l.id = lo.id_lista WHERE l.nombre = 'TipoCliente' AND upper(lo.nombre) = upper('"&SUBSTITUTE(TRIM(I5),"'","''")&"') AND lo.estado = 1 LIMIT 1)")&", p_id_tipo_persona => "&IF(TRIM(H5&"")="","NULL","(SELECT lo.id FROM gen_lista_opciones lo JOIN gen_lista l ON l.id = lo.id_lista WHERE l.nombre = 'TipoPersona' AND upper(lo.nombre) = upper('"&SUBSTITUTE(TRIM(H5),"'","''")&"') AND lo.estado = 1 LIMIT 1)")&", p_nombres => "&IF(TRIM(E5&"")="","NULL","'"&SUBSTITUTE(TRIM(E5),"'","''")&"'")&", p_apellido_paterno => "&IF(TRIM(F5&"")="","NULL","'"&SUBSTITUTE(TRIM(F5),"'","''")&"'")&", p_apellido_materno => "&IF(TRIM(G5&"")="","NULL","'"&SUBSTITUTE(TRIM(G5),"'","''")&"'")&", p_id_tipo_documento => "&IF(TRIM(B5&"")="","NULL","(SELECT lo.id FROM gen_lista_opciones lo JOIN gen_lista l ON l.id = lo.id_lista WHERE l.nombre = 'TipoDocumento' AND upper(lo.nombre) = upper('"&SUBSTITUTE(TRIM(B5),"'","''")&"') AND lo.estado = 1 LIMIT 1)")&", p_numero_documento => "&IF(TRIM(C5&"")="","NULL","'"&SUBSTITUTE(TRIM(C5),"'","''")&"'")&", p_telefono => "&IF(TRIM(L5&"")="","NULL","'"&SUBSTITUTE(TRIM(L5),"'","''")&"'")&", p_email => "&IF(TRIM(M5&"")="","NULL","'"&SUBSTITUTE(TRIM(M5),"'","''")&"'")&", p_observacion => "&IF(TRIM(O5&"")="","NULL","'"&SUBSTITUTE(TRIM(O5),"'","''")&"'")&", p_direccion => "&IF(TRIM(J5&"")="","NULL","'"&SUBSTITUTE(TRIM(J5),"'","''")&"'")&", p_referencia => "&IF(TRIM(K5&"")="","NULL","'"&SUBSTITUTE(TRIM(K5),"'","''")&"'")&") AS resultado_cliente_"&ROW()&";")
A6: =IF(AND(D6="",E6="",C6=""),"",IF(AND(D6="",E6=""),"FALTA razón social o nombres",IF(AND(C6<>"",SUMPRODUCT(--($C$5:$C$549=C6))>1),"DOCUMENTO DUPLICADO",IF(AND(B6="DNI",C6<>"",LEN(C6&"")<>8),"DNI debe tener 8 dígitos",IF(AND(B6="RUC",C6<>"",LEN(C6&"")<>11),"RUC debe tener 11 dígitos",IF(AND(N6<>"",SUMPRODUCT(--($N$5:$N$549=N6))>1),"CÓDIGO INTERNO DUPLICADO","OK")))))) | B6: RUC | C6: 10448235012 | D6: AGUILAR HERRERA EDILBERTO | H6: Persona Jurídica | I6: Cliente | P6: =IF(A6<>"OK","","SELECT cli_crear_clientes(p_codigo_interno => "&IF(TRIM(N6&"")="","NULL","'"&SUBSTITUTE(TRIM(N6),"'","''")&"'")&", p_razon_social => "&IF(TRIM(D6&"")="","NULL","'"&SUBSTITUTE(TRIM(D6),"'","''")&"'")&", p_id_tipo_cliente => "&IF(TRIM(I6&"")="","NULL","(SELECT lo.id FROM gen_lista_opciones lo JOIN gen_lista l ON l.id = lo.id_lista WHERE l.nombre = 'TipoCliente' AND upper(lo.nombre) = upper('"&SUBSTITUTE(TRIM(I6),"'","''")&"') AND lo.estado = 1 LIMIT 1)")&", p_id_tipo_persona => "&IF(TRIM(H6&"")="","NULL","(SELECT lo.id FROM gen_lista_opciones lo JOIN gen_lista l ON l.id = lo.id_lista WHERE l.nombre = 'TipoPersona' AND upper(lo.nombre) = upper('"&SUBSTITUTE(TRIM(H6),"'","''")&"') AND lo.estado = 1 LIMIT 1)")&", p_nombres => "&IF(TRIM(E6&"")="","NULL","'"&SUBSTITUTE(TRIM(E6),"'","''")&"'")&", p_apellido_paterno => "&IF(TRIM(F6&"")="","NULL","'"&SUBSTITUTE(TRIM(F6),"'","''")&"'")&", p_apellido_materno => "&IF(TRIM(G6&"")="","NULL","'"&SUBSTITUTE(TRIM(G6),"'","''")&"'")&", p_id_tipo_documento => "&IF(TRIM(B6&"")="","NULL","(SELECT lo.id FROM gen_lista_opciones lo JOIN gen_lista l ON l.id = lo.id_lista WHERE l.nombre = 'TipoDocumento' AND upper(lo.nombre) = upper('"&SUBSTITUTE(TRIM(B6),"'","''")&"') AND lo.estado = 1 LIMIT 1)")&", p_numero_documento => "&IF(TRIM(C6&"")="","NULL","'"&SUBSTITUTE(TRIM(C6),"'","''")&"'")&", p_telefono => "&IF(TRIM(L6&"")="","NULL","'"&SUBSTITUTE(TRIM(L6),"'","''")&"'")&", p_email => "&IF(TRIM(M6&"")="","NULL","'"&SUBSTITUTE(TRIM(M6),"'","''")&"'")&", p_observacion => "&IF(TRIM(O6&"")="","NULL","'"&SUBSTITUTE(TRIM(O6),"'","''")&"'")&", p_direccion => "&IF(TRIM(J6&"")="","NULL","'"&SUBSTITUTE(TRIM(J6),"'","''")&"'")&", p_referencia => "&IF(TRIM(K6&"")="","NULL","'"&SUBSTITUTE(TRIM(K6),"'","''")&"'")&") AS resultado_cliente_"&ROW()&";")
A7: =IF(AND(D7="",E7="",C7=""),"",IF(AND(D7="",E7=""),"FALTA razón social o nombres",IF(AND(C7<>"",SUMPRODUCT(--($C$5:$C$549=C7))>1),"DOCUMENTO DUPLICADO",IF(AND(B7="DNI",C7<>"",LEN(C7&"")<>8),"DNI debe tener 8 dígitos",IF(AND(B7="RUC",C7<>"",LEN(C7&"")<>11),"RUC debe tener 11 dígitos",IF(AND(N7<>"",SUMPRODUCT(--($N$5:$N$549=N7))>1),"CÓDIGO INTERNO DUPLICADO","OK")))))) | B7: RUC | C7: 20604549401 | D7: AIRPROJECT & CARBIDE PERU S.A.C. - AIRPROJECT & CARBIDE S.A.C. | H7: Persona Jurídica | I7: Proveedor | J7: MZA. B LOTE. 8 OTR. CP SOL Y CAMPO (COSTADO GRIFO CAMPO SOL) | P7: =IF(A7<>"OK","","SELECT cli_crear_clientes(p_codigo_interno => "&IF(TRIM(N7&"")="","NULL","'"&SUBSTITUTE(TRIM(N7),"'","''")&"'")&", p_razon_social => "&IF(TRIM(D7&"")="","NULL","'"&SUBSTITUTE(TRIM(D7),"'","''")&"'")&", p_id_tipo_cliente => "&IF(TRIM(I7&"")="","NULL","(SELECT lo.id FROM gen_lista_opciones lo JOIN gen_lista l ON l.id = lo.id_lista WHERE l.nombre = 'TipoCliente' AND upper(lo.nombre) = upper('"&SUBSTITUTE(TRIM(I7),"'","''")&"') AND lo.estado = 1 LIMIT 1)")&", p_id_tipo_persona => "&IF(TRIM(H7&"")="","NULL","(SELECT lo.id FROM gen_lista_opciones lo JOIN gen_lista l ON l.id = lo.id_lista WHERE l.nombre = 'TipoPersona' AND upper(lo.nombre) = upper('"&SUBSTITUTE(TRIM(H7),"'","''")&"') AND lo.estado = 1 LIMIT 1)")&", p_nombres => "&IF(TRIM(E7&"")="","NULL","'"&SUBSTITUTE(TRIM(E7),"'","''")&"'")&", p_apellido_paterno => "&IF(TRIM(F7&"")="","NULL","'"&SUBSTITUTE(TRIM(F7),"'","''")&"'")&", p_apellido_materno => "&IF(TRIM(G7&"")="","NULL","'"&SUBSTITUTE(TRIM(G7),"'","''")&"'")&", p_id_tipo_documento => "&IF(TRIM(B7&"")="","NULL","(SELECT lo.id FROM gen_lista_opciones lo JOIN gen_lista l ON l.id = lo.id_lista WHERE l.nombre = 'TipoDocumento' AND upper(lo.nombre) = upper('"&SUBSTITUTE(TRIM(B7),"'","''")&"') AND lo.estado = 1 LIMIT 1)")&", p_numero_documento => "&IF(TRIM(C7&"")="","NULL","'"&SUBSTITUTE(TRIM(C7),"'","''")&"'")&", p_telefono => "&IF(TRIM(L7&"")="","NULL","'"&SUBSTITUTE(TRIM(L7),"'","''")&"'")&", p_email => "&IF(TRIM(M7&"")="","NULL","'"&SUBSTITUTE(TRIM(M7),"'","''")&"'")&", p_observacion => "&IF(TRIM(O7&"")="","NULL","'"&SUBSTITUTE(TRIM(O7),"'","''")&"'")&", p_direccion => "&IF(TRIM(J7&"")="","NULL","'"&SUBSTITUTE(TRIM(J7),"'","''")&"'")&", p_referencia => "&IF(TRIM(K7&"")="","NULL","'"&SUBSTITUTE(TRIM(K7),"'","''")&"'")&") AS resultado_cliente_"&ROW()&";")
A8: =IF(AND(D8="",E8="",C8=""),"",IF(AND(D8="",E8=""),"FALTA razón social o nombres",IF(AND(C8<>"",SUMPRODUCT(--($C$5:$C$549=C8))>1),"DOCUMENTO DUPLICADO",IF(AND(B8="DNI",C8<>"",LEN(C8&"")<>8),"DNI debe tener 8 dígitos",IF(AND(B8="RUC",C8<>"",LEN(C8&"")<>11),"RUC debe tener 11 dígitos",IF(AND(N8<>"",SUMPRODUCT(--($N$5:$N$549=N8))>1),"CÓDIGO INTERNO DUPLICADO","OK")))))) | B8: RUC | C8: 20480823860 | D8: ALIAZIONE COSTRUZIONE E SALDATURA E.I.R.L. | H8: Persona Jurídica | I8: Cliente | P8: =IF(A8<>"OK","","SELECT cli_crear_clientes(p_codigo_interno => "&IF(TRIM(N8&"")="","NULL","'"&SUBSTITUTE(TRIM(N8),"'","''")&"'")&", p_razon_social => "&IF(TRIM(D8&"")="","NULL","'"&SUBSTITUTE(TRIM(D8),"'","''")&"'")&", p_id_tipo_cliente => "&IF(TRIM(I8&"")="","NULL","(SELECT lo.id FROM gen_lista_opciones lo JOIN gen_lista l ON l.id = lo.id_lista WHERE l.nombre = 'TipoCliente' AND upper(lo.nombre) = upper('"&SUBSTITUTE(TRIM(I8),"'","''")&"') AND lo.estado = 1 LIMIT 1)")&", p_id_tipo_persona => "&IF(TRIM(H8&"")="","NULL","(SELECT lo.id FROM gen_lista_opciones lo JOIN gen_lista l ON l.id = lo.id_lista WHERE l.nombre = 'TipoPersona' AND upper(lo.nombre) = upper('"&SUBSTITUTE(TRIM(H8),"'","''")&"') AND lo.estado = 1 LIMIT 1)")&", p_nombres => "&IF(TRIM(E8&"")="","NULL","'"&SUBSTITUTE(TRIM(E8),"'","''")&"'")&", p_apellido_paterno => "&IF(TRIM(F8&"")="","NULL","'"&SUBSTITUTE(TRIM(F8),"'","''")&"'")&", p_apellido_materno => "&IF(TRIM(G8&"")="","NULL","'"&SUBSTITUTE(TRIM(G8),"'","''")&"'")&", p_id_tipo_documento => "&IF(TRIM(B8&"")="","NULL","(SELECT lo.id FROM gen_lista_opciones lo JOIN gen_lista l ON l.id = lo.id_lista WHERE l.nombre = 'TipoDocumento' AND upper(lo.nombre) = upper('"&SUBSTITUTE(TRIM(B8),"'","''")&"') AND lo.estado = 1 LIMIT 1)")&", p_numero_documento => "&IF(TRIM(C8&"")="","NULL","'"&SUBSTITUTE(TRIM(C8),"'","''")&"'")&", p_telefono => "&IF(TRIM(L8&"")="","NULL","'"&SUBSTITUTE(TRIM(L8),"'","''")&"'")&", p_email => "&IF(TRIM(M8&"")="","NULL","'"&SUBSTITUTE(TRIM(M8),"'","''")&"'")&", p_observacion => "&IF(TRIM(O8&"")="","NULL","'"&SUBSTITUTE(TRIM(O8),"'","''")&"'")&", p_direccion => "&IF(TRIM(J8&"")="","NULL","'"&SUBSTITUTE(TRIM(J8),"'","''")&"'")&", p_referencia => "&IF(TRIM(K8&"")="","NULL","'"&SUBSTITUTE(TRIM(K8),"'","''")&"'")&") AS resultado_cliente_"&ROW()&";")
A9: =IF(AND(D9="",E9="",C9=""),"",IF(AND(D9="",E9=""),"FALTA razón social o nombres",IF(AND(C9<>"",SUMPRODUCT(--($C$5:$C$549=C9))>1),"DOCUMENTO DUPLICADO",IF(AND(B9="DNI",C9<>"",LEN(C9&"")<>8),"DNI debe tener 8 dígitos",IF(AND(B9="RUC",C9<>"",LEN(C9&"")<>11),"RUC debe tener 11 dígitos",IF(AND(N9<>"",SUMPRODUCT(--($N$5:$N$549=N9))>1),"CÓDIGO INTERNO DUPLICADO","OK")))))) | B9: DNI | C9: 41390177 | E9: CARLOS ALBERTO | F9: ALFARO | G9: ACUÑA | H9: Persona Natural | I9: Cliente | P9: =IF(A9<>"OK","","SELECT cli_crear_clientes(p_codigo_interno => "&IF(TRIM(N9&"")="","NULL","'"&SUBSTITUTE(TRIM(N9),"'","''")&"'")&", p_razon_social => "&IF(TRIM(D9&"")="","NULL","'"&SUBSTITUTE(TRIM(D9),"'","''")&"'")&", p_id_tipo_cliente => "&IF(TRIM(I9&"")="","NULL","(SELECT lo.id FROM gen_lista_opciones lo JOIN gen_lista l ON l.id = lo.id_lista WHERE l.nombre = 'TipoCliente' AND upper(lo.nombre) = upper('"&SUBSTITUTE(TRIM(I9),"'","''")&"') AND lo.estado = 1 LIMIT 1)")&", p_id_tipo_persona => "&IF(TRIM(H9&"")="","NULL","(SELECT lo.id FROM gen_lista_opciones lo JOIN gen_lista l ON l.id = lo.id_lista WHERE l.nombre = 'TipoPersona' AND upper(lo.nombre) = upper('"&SUBSTITUTE(TRIM(H9),"'","''")&"') AND lo.estado = 1 LIMIT 1)")&", p_nombres => "&IF(TRIM(E9&"")="","NULL","'"&SUBSTITUTE(TRIM(E9),"'","''")&"'")&", p_apellido_paterno => "&IF(TRIM(F9&"")="","NULL","'"&SUBSTITUTE(TRIM(F9),"'","''")&"'")&", p_apellido_materno => "&IF(TRIM(G9&"")="","NULL","'"&SUBSTITUTE(TRIM(G9),"'","''")&"'")&", p_id_tipo_documento => "&IF(TRIM(B9&"")="","NULL","(SELECT lo.id FROM gen_lista_opciones lo JOIN gen_lista l ON l.id = lo.id_lista WHERE l.nombre = 'TipoDocumento' AND upper(lo.nombre) = upper('"&SUBSTITUTE(TRIM(B9),"'","''")&"') AND lo.estado = 1 LIMIT 1)")&", p_numero_documento => "&IF(TRIM(C9&"")="","NULL","'"&SUBSTITUTE(TRIM(C9),"'","''")&"'")&", p_telefono => "&IF(TRIM(L9&"")="","NULL","'"&SUBSTITUTE(TRIM(L9),"'","''")&"'")&", p_email => "&IF(TRIM(M9&"")="","NULL","'"&SUBSTITUTE(TRIM(M9),"'","''")&"'")&", p_observacion => "&IF(TRIM(O9&"")="","NULL","'"&SUBSTITUTE(TRIM(O9),"'","''")&"'")&", p_direccion => "&IF(TRIM(J9&"")="","NULL","'"&SUBSTITUTE(TRIM(J9),"'","''")&"'")&", p_referencia => "&IF(TRIM(K9&"")="","NULL","'"&SUBSTITUTE(TRIM(K9),"'","''")&"'")&") AS resultado_cliente_"&ROW()&";")
A10: =IF(AND(D10="",E10="",C10=""),"",IF(AND(D10="",E10=""),"FALTA razón social o nombres",IF(AND(C10<>"",SUMPRODUCT(--($C$5:$C$549=C10))>1),"DOCUMENTO DUPLICADO",IF(AND(B10="DNI",C10<>"",LEN(C10&"")<>8),"DNI debe tener 8 dígitos",IF(AND(B10="RUC",C10<>"",LEN(C10&"")<>11),"RUC debe tener 11 dígitos",IF(AND(N10<>"",SUMPRODUCT(--($N$5:$N$549=N10))>1),"CÓDIGO INTERNO DUPLICADO","OK")))))) | B10: DNI | C10: 41554093 | E10: JULIO CESAR | F10: SANTAMARIA | G10: CHAPOÑAN | H10: Persona Natural | I10: Cliente | P10: =IF(A10<>"OK","","SELECT cli_crear_clientes(p_codigo_interno => "&IF(TRIM(N10&"")="","NULL","'"&SUBSTITUTE(TRIM(N10),"'","''")&"'")&", p_razon_social => "&IF(TRIM(D10&"")="","NULL","'"&SUBSTITUTE(TRIM(D10),"'","''")&"'")&", p_id_tipo_cliente => "&IF(TRIM(I10&"")="","NULL","(SELECT lo.id FROM gen_lista_opciones lo JOIN gen_lista l ON l.id = lo.id_lista WHERE l.nombre = 'TipoCliente' AND upper(lo.nombre) = upper('"&SUBSTITUTE(TRIM(I10),"'","''")&"') AND lo.estado = 1 LIMIT 1)")&", p_id_tipo_persona => "&IF(TRIM(H10&"")="","NULL","(SELECT lo.id FROM gen_lista_opciones lo JOIN gen_lista l ON l.id = lo.id_lista WHERE l.nombre = 'TipoPersona' AND upper(lo.nombre) = upper('"&SUBSTITUTE(TRIM(H10),"'","''")&"') AND lo.estado = 1 LIMIT 1)")&", p_nombres => "&IF(TRIM(E10&"")="","NULL","'"&SUBSTITUTE(TRIM(E10),"'","''")&"'")&", p_apellido_paterno => "&IF(TRIM(F10&"")="","NULL","'"&SUBSTITUTE(TRIM(F10),"'","''")&"'")&", p_apellido_materno => "&IF(TRIM(G10&"")="","NULL","'"&SUBSTITUTE(TRIM(G10),"'","''")&"'")&", p_id_tipo_documento => "&IF(TRIM(B10&"")="","NULL","(SELECT lo.id FROM gen_lista_opciones lo JOIN gen_lista l ON l.id = lo.id_lista WHERE l.nombre = 'TipoDocumento' AND upper(lo.nombre) = upper('"&SUBSTITUTE(TRIM(B10),"'","''")&"') AND lo.estado = 1 LIMIT 1)")&", p_numero_documento => "&IF(TRIM(C10&"")="","NULL","'"&SUBSTITUTE(TRIM(C10),"'","''")&"'")&", p_telefono => "&IF(TRIM(L10&"")="","NULL","'"&SUBSTITUTE(TRIM(L10),"'","''")&"'")&", p_email => "&IF(TRIM(M10&"")="","NULL","'"&SUBSTITUTE(TRIM(M10),"'","''")&"'")&", p_observacion => "&IF(TRIM(O10&"")="","NULL","'"&SUBSTITUTE(TRIM(O10),"'","''")&"'")&", p_direccion => "&IF(TRIM(J10&"")="","NULL","'"&SUBSTITUTE(TRIM(J10),"'","''")&"'")&", p_referencia => "&IF(TRIM(K10&"")="","NULL","'"&SUBSTITUTE(TRIM(K10),"'","''")&"'")&") AS resultado_cliente_"&ROW()&";")
A11: =IF(AND(D11="",E11="",C11=""),"",IF(AND(D11="",E11=""),"FALTA razón social o nombres",IF(AND(C11<>"",SUMPRODUCT(--($C$5:$C$549=C11))>1),"DOCUMENTO DUPLICADO",IF(AND(B11="DNI",C11<>"",LEN(C11&"")<>8),"DNI debe tener 8 dígitos",IF(AND(B11="RUC",C11<>"",LEN(C11&"")<>11),"RUC debe tener 11 dígitos",IF(AND(N11<>"",SUMPRODUCT(--($N$5:$N$549=N11))>1),"CÓDIGO INTERNO DUPLICADO","OK")))))) | B11: DNI | C11: 16482081 | E11: MYRIAM ERLINDA | F11: SALDARRIAGA | G11: MEJIA | H11: Persona Natural | I11: Cliente | P11: =IF(A11<>"OK","","SELECT cli_crear_clientes(p_codigo_interno => "&IF(TRIM(N11&"")="","NULL","'"&SUBSTITUTE(TRIM(N11),"'","''")&"'")&", p_razon_social => "&IF(TRIM(D11&"")="","NULL","'"&SUBSTITUTE(TRIM(D11),"'","''")&"'")&", p_id_tipo_cliente => "&IF(TRIM(I11&"")="","NULL","(SELECT lo.id FROM gen_lista_opciones lo JOIN gen_lista l ON l.id = lo.id_lista WHERE l.nombre = 'TipoCliente' AND upper(lo.nombre) = upper('"&SUBSTITUTE(TRIM(I11),"'","''")&"') AND lo.estado = 1 LIMIT 1)")&", p_id_tipo_persona => "&IF(TRIM(H11&"")="","NULL","(SELECT lo.id FROM gen_lista_opciones lo JOIN gen_lista l ON l.id = lo.id_lista WHERE l.nombre = 'TipoPersona' AND upper(lo.nombre) = upper('"&SUBSTITUTE(TRIM(H11),"'","''")&"') AND lo.estado = 1 LIMIT 1)")&", p_nombres => "&IF(TRIM(E11&"")="","NULL","'"&SUBSTITUTE(TRIM(E11),"'","''")&"'")&", p_apellido_paterno => "&IF(TRIM(F11&"")="","NULL","'"&SUBSTITUTE(TRIM(F11),"'","''")&"'")&", p_apellido_materno => "&IF(TRIM(G11&"")="","NULL","'"&SUBSTITUTE(TRIM(G11),"'","''")&"'")&", p_id_tipo_documento => "&IF(TRIM(B11&"")="","NULL","(SELECT lo.id FROM gen_lista_opciones lo JOIN gen_lista l ON l.id = lo.id_lista WHERE l.nombre = 'TipoDocumento' AND upper(lo.nombre) = upper('"&SUBSTITUTE(TRIM(B11),"'","''")&"') AND lo.estado = 1 LIMIT 1)")&", p_numero_documento => "&IF(TRIM(C11&"")="","NULL","'"&SUBSTITUTE(TRIM(C11),"'","''")&"'")&", p_telefono => "&IF(TRIM(L11&"")="","NULL","'"&SUBSTITUTE(TRIM(L11),"'","''")&"'")&", p_email => "&IF(TRIM(M11&"")="","NULL","'"&SUBSTITUTE(TRIM(M11),"'","''")&"'")&", p_observacion => "&IF(TRIM(O11&"")="","NULL","'"&SUBSTITUTE(TRIM(O11),"'","''")&"'")&", p_direccion => "&IF(TRIM(J11&"")="","NULL","'"&SUBSTITUTE(TRIM(J11),"'","''")&"'")&", p_referencia => "&IF(TRIM(K11&"")="","NULL","'"&SUBSTITUTE(TRIM(K11),"'","''")&"'")&") AS resultado_cliente_"&ROW()&";")
A12: =IF(AND(D12="",E12="",C12=""),"",IF(AND(D12="",E12=""),"FALTA razón social o nombres",IF(AND(C12<>"",SUMPRODUCT(--($C$5:$C$549=C12))>1),"DOCUMENTO DUPLICADO",IF(AND(B12="DNI",C12<>"",LEN(C12&"")<>8),"DNI debe tener 8 dígitos",IF(AND(B12="RUC",C12<>"",LEN(C12&"")<>11),"RUC debe tener 11 dígitos",IF(AND(N12<>"",SUMPRODUCT(--($N$5:$N$549=N12))>1),"CÓDIGO INTERNO DUPLICADO","OK")))))) | B12: DNI | C12: 41037767 | E12: ROSARIO DEL PILAR | F12: ROJAS | G12: CABRERA | H12: Persona Natural | I12: Cliente | P12: =IF(A12<>"OK","","SELECT cli_crear_clientes(p_codigo_interno => "&IF(TRIM(N12&"")="","NULL","'"&SUBSTITUTE(TRIM(N12),"'","''")&"'")&", p_razon_social => "&IF(TRIM(D12&"")="","NULL","'"&SUBSTITUTE(TRIM(D12),"'","''")&"'")&", p_id_tipo_cliente => "&IF(TRIM(I12&"")="","NULL","(SELECT lo.id FROM gen_lista_opciones lo JOIN gen_lista l ON l.id = lo.id_lista WHERE l.nombre = 'TipoCliente' AND upper(lo.nombre) = upper('"&SUBSTITUTE(TRIM(I12),"'","''")&"') AND lo.estado = 1 LIMIT 1)")&", p_id_tipo_persona => "&IF(TRIM(H12&"")="","NULL","(SELECT lo.id FROM gen_lista_opciones lo JOIN gen_lista l ON l.id = lo.id_lista WHERE l.nombre = 'TipoPersona' AND upper(lo.nombre) = upper('"&SUBSTITUTE(TRIM(H12),"'","''")&"') AND lo.estado = 1 LIMIT 1)")&", p_nombres => "&IF(TRIM(E12&"")="","NULL","'"&SUBSTITUTE(TRIM(E12),"'","''")&"'")&", p_apellido_paterno => "&IF(TRIM(F12&"")="","NULL","'"&SUBSTITUTE(TRIM(F12),"'","''")&"'")&", p_apellido_materno => "&IF(TRIM(G12&"")="","NULL","'"&SUBSTITUTE(TRIM(G12),"'","''")&"'")&", p_id_tipo_documento => "&IF(TRIM(B12&"")="","NULL","(SELECT lo.id FROM gen_lista_opciones lo JOIN gen_lista l ON l.id = lo.id_lista WHERE l.nombre = 'TipoDocumento' AND upper(lo.nombre) = upper('"&SUBSTITUTE(TRIM(B12),"'","''")&"') AND lo.estado = 1 LIMIT 1)")&", p_numero_documento => "&IF(TRIM(C12&"")="","NULL","'"&SUBSTITUTE(TRIM(C12),"'","''")&"'")&", p_telefono => "&IF(TRIM(L12&"")="","NULL","'"&SUBSTITUTE(TRIM(L12),"'","''")&"'")&", p_email => "&IF(TRIM(M12&"")="","NULL","'"&SUBSTITUTE(TRIM(M12),"'","''")&"'")&", p_observacion => "&IF(TRIM(O12&"")="","NULL","'"&SUBSTITUTE(TRIM(O12),"'","''")&"'")&", p_direccion => "&IF(TRIM(J12&"")="","NULL","'"&SUBSTITUTE(TRIM(J12),"'","''")&"'")&", p_referencia => "&IF(TRIM(K12&"")="","NULL","'"&SUBSTITUTE(TRIM(K12),"'","''")&"'")&") AS resultado_cliente_"&ROW()&";")
A13: =IF(AND(D13="",E13="",C13=""),"",IF(AND(D13="",E13=""),"FALTA razón social o nombres",IF(AND(C13<>"",SUMPRODUCT(--($C$5:$C$549=C13))>1),"DOCUMENTO DUPLICADO",IF(AND(B13="DNI",C13<>"",LEN(C13&"")<>8),"DNI debe tener 8 dígitos",IF(AND(B13="RUC",C13<>"",LEN(C13&"")<>11),"RUC debe tener 11 dígitos",IF(AND(N13<>"",SUMPRODUCT(--($N$5:$N$549=N13))>1),"CÓDIGO INTERNO DUPLICADO","OK")))))) | B13: RUC | C13: 20523386469 | D13: ALTAVISTA INVERSIONES GLOBALES SOCIEDAD ANONIMA CERRADA - AIG S.A.C. | H13: Persona Jurídica | I13: Cliente | P13: =IF(A13<>"OK","","SELECT cli_crear_clientes(p_codigo_interno => "&IF(TRIM(N13&"")="","NULL","'"&SUBSTITUTE(TRIM(N13),"'","''")&"'")&", p_razon_social => "&IF(TRIM(D13&"")="","NULL","'"&SUBSTITUTE(TRIM(D13),"'","''")&"'")&", p_id_tipo_cliente => "&IF(TRIM(I13&"")="","NULL","(SELECT lo.id FROM gen_lista_opciones lo JOIN gen_lista l ON l.id = lo.id_lista WHERE l.nombre = 'TipoCliente' AND upper(lo.nombre) = upper('"&SUBSTITUTE(TRIM(I13),"'","''")&"') AND lo.estado = 1 LIMIT 1)")&", p_id_tipo_persona => "&IF(TRIM(H13&"")="","NULL","(SELECT lo.id FROM gen_lista_opciones lo JOIN gen_lista l ON l.id = lo.id_lista WHERE l.nombre = 'TipoPersona' AND upper(lo.nombre) = upper('"&SUBSTITUTE(TRIM(H13),"'","''")&"') AND lo.estado = 1 LIMIT 1)")&", p_nombres => "&IF(TRIM(E13&"")="","NULL","'"&SUBSTITUTE(TRIM(E13),"'","''")&"'")&", p_apellido_paterno => "&IF(TRIM(F13&"")="","NULL","'"&SUBSTITUTE(TRIM(F13),"'","''")&"'")&", p_apellido_materno => "&IF(TRIM(G13&"")="","NULL","'"&SUBSTITUTE(TRIM(G13),"'","''")&"'")&", p_id_tipo_documento => "&IF(TRIM(B13&"")="","NULL","(SELECT lo.id FROM gen_lista_opciones lo JOIN gen_lista l ON l.id = lo.id_lista WHERE l.nombre = 'TipoDocumento' AND upper(lo.nombre) = upper('"&SUBSTITUTE(TRIM(B13),"'","''")&"') AND lo.estado = 1 LIMIT 1)")&", p_numero_documento => "&IF(TRIM(C13&"")="","NULL","'"&SUBSTITUTE(TRIM(C13),"'","''")&"'")&", p_telefono => "&IF(TRIM(L13&"")="","NULL","'"&SUBSTITUTE(TRIM(L13),"'","''")&"'")&", p_email => "&IF(TRIM(M13&"")="","NULL","'"&SUBSTITUTE(TRIM(M13),"'","''")&"'")&", p_observacion => "&IF(TRIM(O13&"")="","NULL","'"&SUBSTITUTE(TRIM(O13),"'","''")&"'")&", p_direccion => "&IF(TRIM(J13&"")="","NULL","'"&SUBSTITUTE(TRIM(J13),"'","''")&"'")&", p_referencia => "&IF(TRIM(K13&"")="","NULL","'"&SUBSTITUTE(TRIM(K13),"'","''")&"'")&") AS resultado_cliente_"&ROW()&";")
A14: =IF(AND(D14="",E14="",C14=""),"",IF(AND(D14="",E14=""),"FALTA razón social o nombres",IF(AND(C14<>"",SUMPRODUCT(--($C$5:$C$549=C14))>1),"DOCUMENTO DUPLICADO",IF(AND(B14="DNI",C14<>"",LEN(C14&"")<>8),"DNI debe tener 8 dígitos",IF(AND(B14="RUC",C14<>"",LEN(C14&"")<>11),"RUC debe tener 11 dígitos",IF(AND(N14<>"",SUMPRODUCT(--($N$5:$N$549=N14))>1),"CÓDIGO INTERNO DUPLICADO","OK")))))) | B14: DNI | C14: 45370902 | D14: ANGELES CASTRO ELVIN WANDER | H14: Persona Natural | I14: Cliente | P14: =IF(A14<>"OK","","SELECT cli_crear_clientes(p_codigo_interno => "&IF(TRIM(N14&"")="","NULL","'"&SUBSTITUTE(TRIM(N14),"'","''")&"'")&", p_razon_social => "&IF(TRIM(D14&"")="","NULL","'"&SUBSTITUTE(TRIM(D14),"'","''")&"'")&", p_id_tipo_cliente => "&IF(TRIM(I14&"")="","NULL","(SELECT lo.id FROM gen_lista_opciones lo JOIN gen_lista l ON l.id = lo.id_lista WHERE l.nombre = 'TipoCliente' AND upper(lo.nombre) = upper('"&SUBSTITUTE(TRIM(I14),"'","''")&"') AND lo.estado = 1 LIMIT 1)")&", p_id_tipo_persona => "&IF(TRIM(H14&"")="","NULL","(SELECT lo.id FROM gen_lista_opciones lo JOIN gen_lista l ON l.id = lo.id_lista WHERE l.nombre = 'TipoPersona' AND upper(lo.nombre) = upper('"&SUBSTITUTE(TRIM(H14),"'","''")&"') AND lo.estado = 1 LIMIT 1)")&", p_nombres => "&IF(TRIM(E14&"")="","NULL","'"&SUBSTITUTE(TRIM(E14),"'","''")&"'")&", p_apellido_paterno => "&IF(TRIM(F14&"")="","NULL","'"&SUBSTITUTE(TRIM(F14),"'","''")&"'")&", p_apellido_materno => "&IF(TRIM(G14&"")="","NULL","'"&SUBSTITUTE(TRIM(G14),"'","''")&"'")&", p_id_tipo_documento => "&IF(TRIM(B14&"")="","NULL","(SELECT lo.id FROM gen_lista_opciones lo JOIN gen_lista l ON l.id = lo.id_lista WHERE l.nombre = 'TipoDocumento' AND upper(lo.nombre) = upper('"&SUBSTITUTE(TRIM(B14),"'","''")&"') AND lo.estado = 1 LIMIT 1)")&", p_numero_documento => "&IF(TRIM(C14&"")="","NULL","'"&SUBSTITUTE(TRIM(C14),"'","''")&"'")&", p_telefono => "&IF(TRIM(L14&"")="","NULL","'"&SUBSTITUTE(TRIM(L14),"'","''")&"'")&", p_email => "&IF(TRIM(M14&"")="","NULL","'"&SUBSTITUTE(TRIM(M14),"'","''")&"'")&", p_observacion => "&IF(TRIM(O14&"")="","NULL","'"&SUBSTITUTE(TRIM(O14),"'","''")&"'")&", p_direccion => "&IF(TRIM(J14&"")="","NULL","'"&SUBSTITUTE(TRIM(J14),"'","''")&"'")&", p_referencia => "&IF(TRIM(K14&"")="","NULL","'"&SUBSTITUTE(TRIM(K14),"'","''")&"'")&") AS resultado_cliente_"&ROW()&";")
A15: =IF(AND(D15="",E15="",C15=""),"",IF(AND(D15="",E15=""),"FALTA razón social o nombres",IF(AND(C15<>"",SUMPRODUCT(--($C$5:$C$549=C15))>1),"DOCUMENTO DUPLICADO",IF(AND(B15="DNI",C15<>"",LEN(C15&"")<>8),"DNI debe tener 8 dígitos",IF(AND(B15="RUC",C15<>"",LEN(C15&"")<>11),"RUC debe tener 11 dígitos",IF(AND(N15<>"",SUMPRODUCT(--($N$5:$N$549=N15))>1),"CÓDIGO INTERNO DUPLICADO","OK")))))) | B15: SD | C15: 00001 | E15: DAVID | F15: VALDERA | H15: Persona Natural | I15: Cliente | P15: =IF(A15<>"OK","","SELECT cli_crear_clientes(p_codigo_interno => "&IF(TRIM(N15&"")="","NULL","'"&SUBSTITUTE(TRIM(N15),"'","''")&"'")&", p_razon_social => "&IF(TRIM(D15&"")="","NULL","'"&SUBSTITUTE(TRIM(D15),"'","''")&"'")&", p_id_tipo_cliente => "&IF(TRIM(I15&"")="","NULL","(SELECT lo.id FROM gen_lista_opciones lo JOIN gen_lista l ON l.id = lo.id_lista WHERE l.nombre = 'TipoCliente' AND upper(lo.nombre) = upper('"&SUBSTITUTE(TRIM(I15),"'","''")&"') AND lo.estado = 1 LIMIT 1)")&", p_id_tipo_persona => "&IF(TRIM(H15&"")="","NULL","(SELECT lo.id FROM gen_lista_opciones lo JOIN gen_lista l ON l.id = lo.id_lista WHERE l.nombre = 'TipoPersona' AND upper(lo.nombre) = upper('"&SUBSTITUTE(TRIM(H15),"'","''")&"') AND lo.estado = 1 LIMIT 1)")&", p_nombres => "&IF(TRIM(E15&"")="","NULL","'"&SUBSTITUTE(TRIM(E15),"'","''")&"'")&", p_apellido_paterno => "&IF(TRIM(F15&"")="","NULL","'"&SUBSTITUTE(TRIM(F15),"'","''")&"'")&", p_apellido_materno => "&IF(TRIM(G15&"")="","NULL","'"&SUBSTITUTE(TRIM(G15),"'","''")&"'")&", p_id_tipo_documento => "&IF(TRIM(B15&"")="","NULL","(SELECT lo.id FROM gen_lista_opciones lo JOIN gen_lista l ON l.id = lo.id_lista WHERE l.nombre = 'TipoDocumento' AND upper(lo.nombre) = upper('"&SUBSTITUTE(TRIM(B15),"'","''")&"') AND lo.estado = 1 LIMIT 1)")&", p_numero_documento => "&IF(TRIM(C15&"")="","NULL","'"&SUBSTITUTE(TRIM(C15),"'","''")&"'")&", p_telefono => "&IF(TRIM(L15&"")="","NULL","'"&SUBSTITUTE(TRIM(L15),"'","''")&"'")&", p_email => "&IF(TRIM(M15&"")="","NULL","'"&SUBSTITUTE(TRIM(M15),"'","''")&"'")&", p_observacion => "&IF(TRIM(O15&"")="","NULL","'"&SUBSTITUTE(TRIM(O15),"'","''")&"'")&", p_direccion => "&IF(TRIM(J15&"")="","NULL","'"&SUBSTITUTE(TRIM(J15),"'","''")&"'")&", p_referencia => "&IF(TRIM(K15&"")="","NULL","'"&SUBSTITUTE(TRIM(K15),"'","''")&"'")&") AS resultado_cliente_"&ROW()&";")
